<?xml version="1.0" encoding="UTF-8"?>
<!DOCTYPE html PUBLIC "-//W3C//DTD XHTML 1.0 Strict//EN" "http://www.w3.org/TR/xhtml1/DTD/xhtml1-strict.dtd">
<html xmlns="http://www.w3.org/1999/xhtml">
<head>
    <title>自动化测试报告</title>
    <meta name="generator" content="HTMLTestRunner 0.8.2"/>
    <meta http-equiv="Content-Type" content="text/html; charset=UTF-8"/>
    
<style type="text/css" media="screen">
body        { font-family: verdana, arial, helvetica, sans-serif; font-size: 80%; }
table       { font-size: 100%; }
pre         { }

/* -- heading ---------------------------------------------------------------------- */
h1 {
	font-size: 16pt;
	color: gray;
}
.heading {
    margin-top: 0ex;
    margin-bottom: 1ex;
}

.heading .attribute {
    margin-top: 1ex;
    margin-bottom: 0;
}

.heading .description {
    margin-top: 4ex;
    margin-bottom: 6ex;
}

/* -- css div popup ------------------------------------------------------------------------ */
a.popup_link {
}

a.popup_link:hover {
    color: red;
}

.popup_window {
    display: none;
    position: relative;
    left: 0px;
    top: 0px;
    /*border: solid #627173 1px; */
    padding: 10px;
    background-color: #E6E6D6;
    font-family: "Lucida Console", "Courier New", Courier, monospace;
    text-align: left;
    font-size: 8pt;
    width: 500px;
}

}
/* -- report ------------------------------------------------------------------------ */
#show_detail_line {
    margin-top: 3ex;
    margin-bottom: 1ex;
}
#result_table {
    width: 80%;
    border-collapse: collapse;
    border: 1px solid #777;
}
#header_row {
    font-weight: bold;
    color: white;
    background-color: #777;
}
#result_table td {
    border: 1px solid #777;
    padding: 2px;
}
#total_row  { font-weight: bold; }
.passClass  { background-color: #6c6; }
.failClass  { background-color: #c60; }
.errorClass { background-color: #c00; }
.passCase   { color: #6c6; }
.failCase   { color: #c60; font-weight: bold; }
.errorCase  { color: #c00; font-weight: bold; }
.hiddenRow  { display: none; }
.testcase   { margin-left: 2em; }


/* -- ending ---------------------------------------------------------------------- */
#ending {
}

</style>

</head>
<body>
<script language="javascript" type="text/javascript"><!--
output_list = Array();

/* level - 0:Summary; 1:Failed; 2:All */
function showCase(level) {
    trs = document.getElementsByTagName("tr");
    for (var i = 0; i < trs.length; i++) {
        tr = trs[i];
        id = tr.id;
        if (id.substr(0,2) == 'ft') {
            if (level < 1) {
                tr.className = 'hiddenRow';
            }
            else {
                tr.className = '';
            }
        }
        if (id.substr(0,2) == 'pt') {
            if (level > 1) {
                tr.className = '';
            }
            else {
                tr.className = 'hiddenRow';
            }
        }
    }
}


function showClassDetail(cid, count) {
    var id_list = Array(count);
    var toHide = 1;
    for (var i = 0; i < count; i++) {
        tid0 = 't' + cid.substr(1) + '.' + (i+1);
        tid = 'f' + tid0;
        tr = document.getElementById(tid);
        if (!tr) {
            tid = 'p' + tid0;
            tr = document.getElementById(tid);
        }
        id_list[i] = tid;
        if (tr.className) {
            toHide = 0;
        }
    }
    for (var i = 0; i < count; i++) {
        tid = id_list[i];
        if (toHide) {
            document.getElementById('div_'+tid).style.display = 'none'
            document.getElementById(tid).className = 'hiddenRow';
        }
        else {
            document.getElementById(tid).className = '';
        }
    }
}


function showTestDetail(div_id){
    var details_div = document.getElementById(div_id)
    var displayState = details_div.style.display
    // alert(displayState)
    if (displayState != 'block' ) {
        displayState = 'block'
        details_div.style.display = 'block'
    }
    else {
        details_div.style.display = 'none'
    }
}


function html_escape(s) {
    s = s.replace(/&/g,'&amp;');
    s = s.replace(/</g,'&lt;');
    s = s.replace(/>/g,'&gt;');
    return s;
}

/* obsoleted by detail in <div>
function showOutput(id, name) {
    var w = window.open("", //url
                    name,
                    "resizable,scrollbars,status,width=800,height=450");
    d = w.document;
    d.write("<pre>");
    d.write(html_escape(output_list[id]));
    d.write("\n");
    d.write("<a href='javascript:window.close()'>close</a>\n");
    d.write("</pre>\n");
    d.close();
}
*/
--></script>

<div class='heading'>
<h1>自动化测试报告</h1>
<p class='attribute'><strong>Start Time:</strong> 2018-07-12 10:59:29</p>
<p class='attribute'><strong>Duration:</strong> 0:00:00.013991</p>
<p class='attribute'><strong>Status:</strong> Error 13</p>

<p class='description'>第二课堂后台自动化测试报告</p>
</div>



<p id='show_detail_line'>Show
<a href='javascript:showCase(0)'>Summary</a>
<a href='javascript:showCase(1)'>Failed</a>
<a href='javascript:showCase(2)'>All</a>
</p>
<table id='result_table'>
<colgroup>
<col align='left' />
<col align='right' />
<col align='right' />
<col align='right' />
<col align='right' />
<col align='right' />
</colgroup>
<tr id='header_row'>
    <td>Test Group/Test case</td>
    <td>Count</td>
    <td>Pass</td>
    <td>Fail</td>
    <td>Error</td>
    <td>View</td>
</tr>

<tr class='errorClass'>
    <td>test_activity.test_activity</td>
    <td>12</td>
    <td>0</td>
    <td>0</td>
    <td>12</td>
    <td><a href="javascript:showClassDetail('c1',12)">Detail</a></td>
</tr>

<tr id='ft1.1' class='none'>
    <td class='errorCase'><div class='testcase'>test_addactivity_01: 新增不需要签到不需要签退活动</div></td>
    <td colspan='5' align='center'>

    <!--css div popup start-->
    <a class="popup_link" onfocus='this.blur();' href="javascript:showTestDetail('div_ft1.1')" >
        error</a>

    <div id='div_ft1.1' class="popup_window">
        <div style='text-align: right; color:red;cursor:pointer'>
        <a onfocus='this.blur();' onclick="document.getElementById('div_ft1.1').style.display = 'none' " >
           [x]</a>
        </div>
        <pre>
        
ft1.1: Traceback (most recent call last):
  File "C:\Python34\lib\site-packages\selenium\webdriver\common\service.py", line 76, in start
    stdin=PIPE)
  File "C:\Python34\lib\subprocess.py", line 707, in __init__
    restore_signals, start_new_session)
  File "C:\Python34\lib\subprocess.py", line 990, in _execute_child
    startupinfo)
FileNotFoundError: [WinError 2] 系统找不到指定的文件。

During handling of the above exception, another exception occurred:

Traceback (most recent call last):
  File "e:\activity\testcase\test_activity.py", line 23, in setUp
    self.driver=activitypage(webdriver.Chrome(ospath+'/chromedriver.exe'))
  File "C:\Python34\lib\site-packages\selenium\webdriver\chrome\webdriver.py", line 68, in __init__
    self.service.start()
  File "C:\Python34\lib\site-packages\selenium\webdriver\common\service.py", line 83, in start
    os.path.basename(self.path), self.start_error_message)
selenium.common.exceptions.WebDriverException: Message: 'chromedriver.exe' executable needs to be in PATH. Please see https://sites.google.com/a/chromium.org/chromedriver/home

Traceback (most recent call last):
  File "C:\Python34\lib\site-packages\selenium\webdriver\common\service.py", line 76, in start
    stdin=PIPE)
  File "C:\Python34\lib\subprocess.py", line 707, in __init__
    restore_signals, start_new_session)
  File "C:\Python34\lib\subprocess.py", line 990, in _execute_child
    startupinfo)
FileNotFoundError: [WinError 2] 系统找不到指定的文件。

During handling of the above exception, another exception occurred:

Traceback (most recent call last):
  File "e:\activity\testcase\test_activity.py", line 23, in setUp
    self.driver=activitypage(webdriver.Chrome(ospath+'/chromedriver.exe'))
  File "C:\Python34\lib\site-packages\selenium\webdriver\chrome\webdriver.py", line 68, in __init__
    self.service.start()
  File "C:\Python34\lib\site-packages\selenium\webdriver\common\service.py", line 83, in start
    os.path.basename(self.path), self.start_error_message)
selenium.common.exceptions.WebDriverException: Message: 'chromedriver.exe' executable needs to be in PATH. Please see https://sites.google.com/a/chromium.org/chromedriver/home



        </pre>
    </div>
    <!--css div popup end-->

    </td>
</tr>

<tr id='ft1.2' class='none'>
    <td class='errorCase'><div class='testcase'>test_addactivity_02: 新增普通签到不需要签退活动</div></td>
    <td colspan='5' align='center'>

    <!--css div popup start-->
    <a class="popup_link" onfocus='this.blur();' href="javascript:showTestDetail('div_ft1.2')" >
        error</a>

    <div id='div_ft1.2' class="popup_window">
        <div style='text-align: right; color:red;cursor:pointer'>
        <a onfocus='this.blur();' onclick="document.getElementById('div_ft1.2').style.display = 'none' " >
           [x]</a>
        </div>
        <pre>
        
ft1.2: Traceback (most recent call last):
  File "C:\Python34\lib\site-packages\selenium\webdriver\common\service.py", line 76, in start
    stdin=PIPE)
  File "C:\Python34\lib\subprocess.py", line 707, in __init__
    restore_signals, start_new_session)
  File "C:\Python34\lib\subprocess.py", line 990, in _execute_child
    startupinfo)
FileNotFoundError: [WinError 2] 系统找不到指定的文件。

During handling of the above exception, another exception occurred:

Traceback (most recent call last):
  File "e:\activity\testcase\test_activity.py", line 23, in setUp
    self.driver=activitypage(webdriver.Chrome(ospath+'/chromedriver.exe'))
  File "C:\Python34\lib\site-packages\selenium\webdriver\chrome\webdriver.py", line 68, in __init__
    self.service.start()
  File "C:\Python34\lib\site-packages\selenium\webdriver\common\service.py", line 83, in start
    os.path.basename(self.path), self.start_error_message)
selenium.common.exceptions.WebDriverException: Message: 'chromedriver.exe' executable needs to be in PATH. Please see https://sites.google.com/a/chromium.org/chromedriver/home

Traceback (most recent call last):
  File "C:\Python34\lib\site-packages\selenium\webdriver\common\service.py", line 76, in start
    stdin=PIPE)
  File "C:\Python34\lib\subprocess.py", line 707, in __init__
    restore_signals, start_new_session)
  File "C:\Python34\lib\subprocess.py", line 990, in _execute_child
    startupinfo)
FileNotFoundError: [WinError 2] 系统找不到指定的文件。

During handling of the above exception, another exception occurred:

Traceback (most recent call last):
  File "e:\activity\testcase\test_activity.py", line 23, in setUp
    self.driver=activitypage(webdriver.Chrome(ospath+'/chromedriver.exe'))
  File "C:\Python34\lib\site-packages\selenium\webdriver\chrome\webdriver.py", line 68, in __init__
    self.service.start()
  File "C:\Python34\lib\site-packages\selenium\webdriver\common\service.py", line 83, in start
    os.path.basename(self.path), self.start_error_message)
selenium.common.exceptions.WebDriverException: Message: 'chromedriver.exe' executable needs to be in PATH. Please see https://sites.google.com/a/chromium.org/chromedriver/home



        </pre>
    </div>
    <!--css div popup end-->

    </td>
</tr>

<tr id='ft1.3' class='none'>
    <td class='errorCase'><div class='testcase'>test_addactivity_03: 新增扫描签到不需要签退活动</div></td>
    <td colspan='5' align='center'>

    <!--css div popup start-->
    <a class="popup_link" onfocus='this.blur();' href="javascript:showTestDetail('div_ft1.3')" >
        error</a>

    <div id='div_ft1.3' class="popup_window">
        <div style='text-align: right; color:red;cursor:pointer'>
        <a onfocus='this.blur();' onclick="document.getElementById('div_ft1.3').style.display = 'none' " >
           [x]</a>
        </div>
        <pre>
        
ft1.3: Traceback (most recent call last):
  File "C:\Python34\lib\site-packages\selenium\webdriver\common\service.py", line 76, in start
    stdin=PIPE)
  File "C:\Python34\lib\subprocess.py", line 707, in __init__
    restore_signals, start_new_session)
  File "C:\Python34\lib\subprocess.py", line 990, in _execute_child
    startupinfo)
FileNotFoundError: [WinError 2] 系统找不到指定的文件。

During handling of the above exception, another exception occurred:

Traceback (most recent call last):
  File "e:\activity\testcase\test_activity.py", line 23, in setUp
    self.driver=activitypage(webdriver.Chrome(ospath+'/chromedriver.exe'))
  File "C:\Python34\lib\site-packages\selenium\webdriver\chrome\webdriver.py", line 68, in __init__
    self.service.start()
  File "C:\Python34\lib\site-packages\selenium\webdriver\common\service.py", line 83, in start
    os.path.basename(self.path), self.start_error_message)
selenium.common.exceptions.WebDriverException: Message: 'chromedriver.exe' executable needs to be in PATH. Please see https://sites.google.com/a/chromium.org/chromedriver/home

Traceback (most recent call last):
  File "C:\Python34\lib\site-packages\selenium\webdriver\common\service.py", line 76, in start
    stdin=PIPE)
  File "C:\Python34\lib\subprocess.py", line 707, in __init__
    restore_signals, start_new_session)
  File "C:\Python34\lib\subprocess.py", line 990, in _execute_child
    startupinfo)
FileNotFoundError: [WinError 2] 系统找不到指定的文件。

During handling of the above exception, another exception occurred:

Traceback (most recent call last):
  File "e:\activity\testcase\test_activity.py", line 23, in setUp
    self.driver=activitypage(webdriver.Chrome(ospath+'/chromedriver.exe'))
  File "C:\Python34\lib\site-packages\selenium\webdriver\chrome\webdriver.py", line 68, in __init__
    self.service.start()
  File "C:\Python34\lib\site-packages\selenium\webdriver\common\service.py", line 83, in start
    os.path.basename(self.path), self.start_error_message)
selenium.common.exceptions.WebDriverException: Message: 'chromedriver.exe' executable needs to be in PATH. Please see https://sites.google.com/a/chromium.org/chromedriver/home



        </pre>
    </div>
    <!--css div popup end-->

    </td>
</tr>

<tr id='ft1.4' class='none'>
    <td class='errorCase'><div class='testcase'>test_addactivity_04: 新增管理员扫描签到不需要签退活动</div></td>
    <td colspan='5' align='center'>

    <!--css div popup start-->
    <a class="popup_link" onfocus='this.blur();' href="javascript:showTestDetail('div_ft1.4')" >
        error</a>

    <div id='div_ft1.4' class="popup_window">
        <div style='text-align: right; color:red;cursor:pointer'>
        <a onfocus='this.blur();' onclick="document.getElementById('div_ft1.4').style.display = 'none' " >
           [x]</a>
        </div>
        <pre>
        
ft1.4: Traceback (most recent call last):
  File "C:\Python34\lib\site-packages\selenium\webdriver\common\service.py", line 76, in start
    stdin=PIPE)
  File "C:\Python34\lib\subprocess.py", line 707, in __init__
    restore_signals, start_new_session)
  File "C:\Python34\lib\subprocess.py", line 990, in _execute_child
    startupinfo)
FileNotFoundError: [WinError 2] 系统找不到指定的文件。

During handling of the above exception, another exception occurred:

Traceback (most recent call last):
  File "e:\activity\testcase\test_activity.py", line 23, in setUp
    self.driver=activitypage(webdriver.Chrome(ospath+'/chromedriver.exe'))
  File "C:\Python34\lib\site-packages\selenium\webdriver\chrome\webdriver.py", line 68, in __init__
    self.service.start()
  File "C:\Python34\lib\site-packages\selenium\webdriver\common\service.py", line 83, in start
    os.path.basename(self.path), self.start_error_message)
selenium.common.exceptions.WebDriverException: Message: 'chromedriver.exe' executable needs to be in PATH. Please see https://sites.google.com/a/chromium.org/chromedriver/home

Traceback (most recent call last):
  File "C:\Python34\lib\site-packages\selenium\webdriver\common\service.py", line 76, in start
    stdin=PIPE)
  File "C:\Python34\lib\subprocess.py", line 707, in __init__
    restore_signals, start_new_session)
  File "C:\Python34\lib\subprocess.py", line 990, in _execute_child
    startupinfo)
FileNotFoundError: [WinError 2] 系统找不到指定的文件。

During handling of the above exception, another exception occurred:

Traceback (most recent call last):
  File "e:\activity\testcase\test_activity.py", line 23, in setUp
    self.driver=activitypage(webdriver.Chrome(ospath+'/chromedriver.exe'))
  File "C:\Python34\lib\site-packages\selenium\webdriver\chrome\webdriver.py", line 68, in __init__
    self.service.start()
  File "C:\Python34\lib\site-packages\selenium\webdriver\common\service.py", line 83, in start
    os.path.basename(self.path), self.start_error_message)
selenium.common.exceptions.WebDriverException: Message: 'chromedriver.exe' executable needs to be in PATH. Please see https://sites.google.com/a/chromium.org/chromedriver/home



        </pre>
    </div>
    <!--css div popup end-->

    </td>
</tr>

<tr id='ft1.5' class='none'>
    <td class='errorCase'><div class='testcase'>test_addactivity_05: 新增验票签到不需要签退活动</div></td>
    <td colspan='5' align='center'>

    <!--css div popup start-->
    <a class="popup_link" onfocus='this.blur();' href="javascript:showTestDetail('div_ft1.5')" >
        error</a>

    <div id='div_ft1.5' class="popup_window">
        <div style='text-align: right; color:red;cursor:pointer'>
        <a onfocus='this.blur();' onclick="document.getElementById('div_ft1.5').style.display = 'none' " >
           [x]</a>
        </div>
        <pre>
        
ft1.5: Traceback (most recent call last):
  File "C:\Python34\lib\site-packages\selenium\webdriver\common\service.py", line 76, in start
    stdin=PIPE)
  File "C:\Python34\lib\subprocess.py", line 707, in __init__
    restore_signals, start_new_session)
  File "C:\Python34\lib\subprocess.py", line 990, in _execute_child
    startupinfo)
FileNotFoundError: [WinError 2] 系统找不到指定的文件。

During handling of the above exception, another exception occurred:

Traceback (most recent call last):
  File "e:\activity\testcase\test_activity.py", line 23, in setUp
    self.driver=activitypage(webdriver.Chrome(ospath+'/chromedriver.exe'))
  File "C:\Python34\lib\site-packages\selenium\webdriver\chrome\webdriver.py", line 68, in __init__
    self.service.start()
  File "C:\Python34\lib\site-packages\selenium\webdriver\common\service.py", line 83, in start
    os.path.basename(self.path), self.start_error_message)
selenium.common.exceptions.WebDriverException: Message: 'chromedriver.exe' executable needs to be in PATH. Please see https://sites.google.com/a/chromium.org/chromedriver/home

Traceback (most recent call last):
  File "C:\Python34\lib\site-packages\selenium\webdriver\common\service.py", line 76, in start
    stdin=PIPE)
  File "C:\Python34\lib\subprocess.py", line 707, in __init__
    restore_signals, start_new_session)
  File "C:\Python34\lib\subprocess.py", line 990, in _execute_child
    startupinfo)
FileNotFoundError: [WinError 2] 系统找不到指定的文件。

During handling of the above exception, another exception occurred:

Traceback (most recent call last):
  File "e:\activity\testcase\test_activity.py", line 23, in setUp
    self.driver=activitypage(webdriver.Chrome(ospath+'/chromedriver.exe'))
  File "C:\Python34\lib\site-packages\selenium\webdriver\chrome\webdriver.py", line 68, in __init__
    self.service.start()
  File "C:\Python34\lib\site-packages\selenium\webdriver\common\service.py", line 83, in start
    os.path.basename(self.path), self.start_error_message)
selenium.common.exceptions.WebDriverException: Message: 'chromedriver.exe' executable needs to be in PATH. Please see https://sites.google.com/a/chromium.org/chromedriver/home



        </pre>
    </div>
    <!--css div popup end-->

    </td>
</tr>

<tr id='ft1.6' class='none'>
    <td class='errorCase'><div class='testcase'>test_addactivity_06: 新增不需要签到普通签退活动</div></td>
    <td colspan='5' align='center'>

    <!--css div popup start-->
    <a class="popup_link" onfocus='this.blur();' href="javascript:showTestDetail('div_ft1.6')" >
        error</a>

    <div id='div_ft1.6' class="popup_window">
        <div style='text-align: right; color:red;cursor:pointer'>
        <a onfocus='this.blur();' onclick="document.getElementById('div_ft1.6').style.display = 'none' " >
           [x]</a>
        </div>
        <pre>
        
ft1.6: Traceback (most recent call last):
  File "C:\Python34\lib\site-packages\selenium\webdriver\common\service.py", line 76, in start
    stdin=PIPE)
  File "C:\Python34\lib\subprocess.py", line 707, in __init__
    restore_signals, start_new_session)
  File "C:\Python34\lib\subprocess.py", line 990, in _execute_child
    startupinfo)
FileNotFoundError: [WinError 2] 系统找不到指定的文件。

During handling of the above exception, another exception occurred:

Traceback (most recent call last):
  File "e:\activity\testcase\test_activity.py", line 23, in setUp
    self.driver=activitypage(webdriver.Chrome(ospath+'/chromedriver.exe'))
  File "C:\Python34\lib\site-packages\selenium\webdriver\chrome\webdriver.py", line 68, in __init__
    self.service.start()
  File "C:\Python34\lib\site-packages\selenium\webdriver\common\service.py", line 83, in start
    os.path.basename(self.path), self.start_error_message)
selenium.common.exceptions.WebDriverException: Message: 'chromedriver.exe' executable needs to be in PATH. Please see https://sites.google.com/a/chromium.org/chromedriver/home

Traceback (most recent call last):
  File "C:\Python34\lib\site-packages\selenium\webdriver\common\service.py", line 76, in start
    stdin=PIPE)
  File "C:\Python34\lib\subprocess.py", line 707, in __init__
    restore_signals, start_new_session)
  File "C:\Python34\lib\subprocess.py", line 990, in _execute_child
    startupinfo)
FileNotFoundError: [WinError 2] 系统找不到指定的文件。

During handling of the above exception, another exception occurred:

Traceback (most recent call last):
  File "e:\activity\testcase\test_activity.py", line 23, in setUp
    self.driver=activitypage(webdriver.Chrome(ospath+'/chromedriver.exe'))
  File "C:\Python34\lib\site-packages\selenium\webdriver\chrome\webdriver.py", line 68, in __init__
    self.service.start()
  File "C:\Python34\lib\site-packages\selenium\webdriver\common\service.py", line 83, in start
    os.path.basename(self.path), self.start_error_message)
selenium.common.exceptions.WebDriverException: Message: 'chromedriver.exe' executable needs to be in PATH. Please see https://sites.google.com/a/chromium.org/chromedriver/home



        </pre>
    </div>
    <!--css div popup end-->

    </td>
</tr>

<tr id='ft1.7' class='none'>
    <td class='errorCase'><div class='testcase'>test_addactivity_07: 新增不需要签到扫描签退活动</div></td>
    <td colspan='5' align='center'>

    <!--css div popup start-->
    <a class="popup_link" onfocus='this.blur();' href="javascript:showTestDetail('div_ft1.7')" >
        error</a>

    <div id='div_ft1.7' class="popup_window">
        <div style='text-align: right; color:red;cursor:pointer'>
        <a onfocus='this.blur();' onclick="document.getElementById('div_ft1.7').style.display = 'none' " >
           [x]</a>
        </div>
        <pre>
        
ft1.7: Traceback (most recent call last):
  File "C:\Python34\lib\site-packages\selenium\webdriver\common\service.py", line 76, in start
    stdin=PIPE)
  File "C:\Python34\lib\subprocess.py", line 707, in __init__
    restore_signals, start_new_session)
  File "C:\Python34\lib\subprocess.py", line 990, in _execute_child
    startupinfo)
FileNotFoundError: [WinError 2] 系统找不到指定的文件。

During handling of the above exception, another exception occurred:

Traceback (most recent call last):
  File "e:\activity\testcase\test_activity.py", line 23, in setUp
    self.driver=activitypage(webdriver.Chrome(ospath+'/chromedriver.exe'))
  File "C:\Python34\lib\site-packages\selenium\webdriver\chrome\webdriver.py", line 68, in __init__
    self.service.start()
  File "C:\Python34\lib\site-packages\selenium\webdriver\common\service.py", line 83, in start
    os.path.basename(self.path), self.start_error_message)
selenium.common.exceptions.WebDriverException: Message: 'chromedriver.exe' executable needs to be in PATH. Please see https://sites.google.com/a/chromium.org/chromedriver/home

Traceback (most recent call last):
  File "C:\Python34\lib\site-packages\selenium\webdriver\common\service.py", line 76, in start
    stdin=PIPE)
  File "C:\Python34\lib\subprocess.py", line 707, in __init__
    restore_signals, start_new_session)
  File "C:\Python34\lib\subprocess.py", line 990, in _execute_child
    startupinfo)
FileNotFoundError: [WinError 2] 系统找不到指定的文件。

During handling of the above exception, another exception occurred:

Traceback (most recent call last):
  File "e:\activity\testcase\test_activity.py", line 23, in setUp
    self.driver=activitypage(webdriver.Chrome(ospath+'/chromedriver.exe'))
  File "C:\Python34\lib\site-packages\selenium\webdriver\chrome\webdriver.py", line 68, in __init__
    self.service.start()
  File "C:\Python34\lib\site-packages\selenium\webdriver\common\service.py", line 83, in start
    os.path.basename(self.path), self.start_error_message)
selenium.common.exceptions.WebDriverException: Message: 'chromedriver.exe' executable needs to be in PATH. Please see https://sites.google.com/a/chromium.org/chromedriver/home



        </pre>
    </div>
    <!--css div popup end-->

    </td>
</tr>

<tr id='ft1.8' class='none'>
    <td class='errorCase'><div class='testcase'>test_addactivity_08: 新增不需要签到管理员扫描签退活动</div></td>
    <td colspan='5' align='center'>

    <!--css div popup start-->
    <a class="popup_link" onfocus='this.blur();' href="javascript:showTestDetail('div_ft1.8')" >
        error</a>

    <div id='div_ft1.8' class="popup_window">
        <div style='text-align: right; color:red;cursor:pointer'>
        <a onfocus='this.blur();' onclick="document.getElementById('div_ft1.8').style.display = 'none' " >
           [x]</a>
        </div>
        <pre>
        
ft1.8: Traceback (most recent call last):
  File "C:\Python34\lib\site-packages\selenium\webdriver\common\service.py", line 76, in start
    stdin=PIPE)
  File "C:\Python34\lib\subprocess.py", line 707, in __init__
    restore_signals, start_new_session)
  File "C:\Python34\lib\subprocess.py", line 990, in _execute_child
    startupinfo)
FileNotFoundError: [WinError 2] 系统找不到指定的文件。

During handling of the above exception, another exception occurred:

Traceback (most recent call last):
  File "e:\activity\testcase\test_activity.py", line 23, in setUp
    self.driver=activitypage(webdriver.Chrome(ospath+'/chromedriver.exe'))
  File "C:\Python34\lib\site-packages\selenium\webdriver\chrome\webdriver.py", line 68, in __init__
    self.service.start()
  File "C:\Python34\lib\site-packages\selenium\webdriver\common\service.py", line 83, in start
    os.path.basename(self.path), self.start_error_message)
selenium.common.exceptions.WebDriverException: Message: 'chromedriver.exe' executable needs to be in PATH. Please see https://sites.google.com/a/chromium.org/chromedriver/home

Traceback (most recent call last):
  File "C:\Python34\lib\site-packages\selenium\webdriver\common\service.py", line 76, in start
    stdin=PIPE)
  File "C:\Python34\lib\subprocess.py", line 707, in __init__
    restore_signals, start_new_session)
  File "C:\Python34\lib\subprocess.py", line 990, in _execute_child
    startupinfo)
FileNotFoundError: [WinError 2] 系统找不到指定的文件。

During handling of the above exception, another exception occurred:

Traceback (most recent call last):
  File "e:\activity\testcase\test_activity.py", line 23, in setUp
    self.driver=activitypage(webdriver.Chrome(ospath+'/chromedriver.exe'))
  File "C:\Python34\lib\site-packages\selenium\webdriver\chrome\webdriver.py", line 68, in __init__
    self.service.start()
  File "C:\Python34\lib\site-packages\selenium\webdriver\common\service.py", line 83, in start
    os.path.basename(self.path), self.start_error_message)
selenium.common.exceptions.WebDriverException: Message: 'chromedriver.exe' executable needs to be in PATH. Please see https://sites.google.com/a/chromium.org/chromedriver/home



        </pre>
    </div>
    <!--css div popup end-->

    </td>
</tr>

<tr id='ft1.9' class='none'>
    <td class='errorCase'><div class='testcase'>test_addactivity_09: 新增不需要签到验票签退活动</div></td>
    <td colspan='5' align='center'>

    <!--css div popup start-->
    <a class="popup_link" onfocus='this.blur();' href="javascript:showTestDetail('div_ft1.9')" >
        error</a>

    <div id='div_ft1.9' class="popup_window">
        <div style='text-align: right; color:red;cursor:pointer'>
        <a onfocus='this.blur();' onclick="document.getElementById('div_ft1.9').style.display = 'none' " >
           [x]</a>
        </div>
        <pre>
        
ft1.9: Traceback (most recent call last):
  File "C:\Python34\lib\site-packages\selenium\webdriver\common\service.py", line 76, in start
    stdin=PIPE)
  File "C:\Python34\lib\subprocess.py", line 707, in __init__
    restore_signals, start_new_session)
  File "C:\Python34\lib\subprocess.py", line 990, in _execute_child
    startupinfo)
FileNotFoundError: [WinError 2] 系统找不到指定的文件。

During handling of the above exception, another exception occurred:

Traceback (most recent call last):
  File "e:\activity\testcase\test_activity.py", line 23, in setUp
    self.driver=activitypage(webdriver.Chrome(ospath+'/chromedriver.exe'))
  File "C:\Python34\lib\site-packages\selenium\webdriver\chrome\webdriver.py", line 68, in __init__
    self.service.start()
  File "C:\Python34\lib\site-packages\selenium\webdriver\common\service.py", line 83, in start
    os.path.basename(self.path), self.start_error_message)
selenium.common.exceptions.WebDriverException: Message: 'chromedriver.exe' executable needs to be in PATH. Please see https://sites.google.com/a/chromium.org/chromedriver/home

Traceback (most recent call last):
  File "C:\Python34\lib\site-packages\selenium\webdriver\common\service.py", line 76, in start
    stdin=PIPE)
  File "C:\Python34\lib\subprocess.py", line 707, in __init__
    restore_signals, start_new_session)
  File "C:\Python34\lib\subprocess.py", line 990, in _execute_child
    startupinfo)
FileNotFoundError: [WinError 2] 系统找不到指定的文件。

During handling of the above exception, another exception occurred:

Traceback (most recent call last):
  File "e:\activity\testcase\test_activity.py", line 23, in setUp
    self.driver=activitypage(webdriver.Chrome(ospath+'/chromedriver.exe'))
  File "C:\Python34\lib\site-packages\selenium\webdriver\chrome\webdriver.py", line 68, in __init__
    self.service.start()
  File "C:\Python34\lib\site-packages\selenium\webdriver\common\service.py", line 83, in start
    os.path.basename(self.path), self.start_error_message)
selenium.common.exceptions.WebDriverException: Message: 'chromedriver.exe' executable needs to be in PATH. Please see https://sites.google.com/a/chromium.org/chromedriver/home



        </pre>
    </div>
    <!--css div popup end-->

    </td>
</tr>

<tr id='ft1.10' class='none'>
    <td class='errorCase'><div class='testcase'>test_addactivity_10: 新增普通签到普通签退活动</div></td>
    <td colspan='5' align='center'>

    <!--css div popup start-->
    <a class="popup_link" onfocus='this.blur();' href="javascript:showTestDetail('div_ft1.10')" >
        error</a>

    <div id='div_ft1.10' class="popup_window">
        <div style='text-align: right; color:red;cursor:pointer'>
        <a onfocus='this.blur();' onclick="document.getElementById('div_ft1.10').style.display = 'none' " >
           [x]</a>
        </div>
        <pre>
        
ft1.10: Traceback (most recent call last):
  File "C:\Python34\lib\site-packages\selenium\webdriver\common\service.py", line 76, in start
    stdin=PIPE)
  File "C:\Python34\lib\subprocess.py", line 707, in __init__
    restore_signals, start_new_session)
  File "C:\Python34\lib\subprocess.py", line 990, in _execute_child
    startupinfo)
FileNotFoundError: [WinError 2] 系统找不到指定的文件。

During handling of the above exception, another exception occurred:

Traceback (most recent call last):
  File "e:\activity\testcase\test_activity.py", line 23, in setUp
    self.driver=activitypage(webdriver.Chrome(ospath+'/chromedriver.exe'))
  File "C:\Python34\lib\site-packages\selenium\webdriver\chrome\webdriver.py", line 68, in __init__
    self.service.start()
  File "C:\Python34\lib\site-packages\selenium\webdriver\common\service.py", line 83, in start
    os.path.basename(self.path), self.start_error_message)
selenium.common.exceptions.WebDriverException: Message: 'chromedriver.exe' executable needs to be in PATH. Please see https://sites.google.com/a/chromium.org/chromedriver/home

Traceback (most recent call last):
  File "C:\Python34\lib\site-packages\selenium\webdriver\common\service.py", line 76, in start
    stdin=PIPE)
  File "C:\Python34\lib\subprocess.py", line 707, in __init__
    restore_signals, start_new_session)
  File "C:\Python34\lib\subprocess.py", line 990, in _execute_child
    startupinfo)
FileNotFoundError: [WinError 2] 系统找不到指定的文件。

During handling of the above exception, another exception occurred:

Traceback (most recent call last):
  File "e:\activity\testcase\test_activity.py", line 23, in setUp
    self.driver=activitypage(webdriver.Chrome(ospath+'/chromedriver.exe'))
  File "C:\Python34\lib\site-packages\selenium\webdriver\chrome\webdriver.py", line 68, in __init__
    self.service.start()
  File "C:\Python34\lib\site-packages\selenium\webdriver\common\service.py", line 83, in start
    os.path.basename(self.path), self.start_error_message)
selenium.common.exceptions.WebDriverException: Message: 'chromedriver.exe' executable needs to be in PATH. Please see https://sites.google.com/a/chromium.org/chromedriver/home



        </pre>
    </div>
    <!--css div popup end-->

    </td>
</tr>

<tr id='ft1.11' class='none'>
    <td class='errorCase'><div class='testcase'>test_audit1: 一审活动</div></td>
    <td colspan='5' align='center'>

    <!--css div popup start-->
    <a class="popup_link" onfocus='this.blur();' href="javascript:showTestDetail('div_ft1.11')" >
        error</a>

    <div id='div_ft1.11' class="popup_window">
        <div style='text-align: right; color:red;cursor:pointer'>
        <a onfocus='this.blur();' onclick="document.getElementById('div_ft1.11').style.display = 'none' " >
           [x]</a>
        </div>
        <pre>
        
ft1.11: Traceback (most recent call last):
  File "C:\Python34\lib\site-packages\selenium\webdriver\common\service.py", line 76, in start
    stdin=PIPE)
  File "C:\Python34\lib\subprocess.py", line 707, in __init__
    restore_signals, start_new_session)
  File "C:\Python34\lib\subprocess.py", line 990, in _execute_child
    startupinfo)
FileNotFoundError: [WinError 2] 系统找不到指定的文件。

During handling of the above exception, another exception occurred:

Traceback (most recent call last):
  File "e:\activity\testcase\test_activity.py", line 23, in setUp
    self.driver=activitypage(webdriver.Chrome(ospath+'/chromedriver.exe'))
  File "C:\Python34\lib\site-packages\selenium\webdriver\chrome\webdriver.py", line 68, in __init__
    self.service.start()
  File "C:\Python34\lib\site-packages\selenium\webdriver\common\service.py", line 83, in start
    os.path.basename(self.path), self.start_error_message)
selenium.common.exceptions.WebDriverException: Message: 'chromedriver.exe' executable needs to be in PATH. Please see https://sites.google.com/a/chromium.org/chromedriver/home

Traceback (most recent call last):
  File "C:\Python34\lib\site-packages\selenium\webdriver\common\service.py", line 76, in start
    stdin=PIPE)
  File "C:\Python34\lib\subprocess.py", line 707, in __init__
    restore_signals, start_new_session)
  File "C:\Python34\lib\subprocess.py", line 990, in _execute_child
    startupinfo)
FileNotFoundError: [WinError 2] 系统找不到指定的文件。

During handling of the above exception, another exception occurred:

Traceback (most recent call last):
  File "e:\activity\testcase\test_activity.py", line 23, in setUp
    self.driver=activitypage(webdriver.Chrome(ospath+'/chromedriver.exe'))
  File "C:\Python34\lib\site-packages\selenium\webdriver\chrome\webdriver.py", line 68, in __init__
    self.service.start()
  File "C:\Python34\lib\site-packages\selenium\webdriver\common\service.py", line 83, in start
    os.path.basename(self.path), self.start_error_message)
selenium.common.exceptions.WebDriverException: Message: 'chromedriver.exe' executable needs to be in PATH. Please see https://sites.google.com/a/chromium.org/chromedriver/home



        </pre>
    </div>
    <!--css div popup end-->

    </td>
</tr>

<tr id='ft1.12' class='none'>
    <td class='errorCase'><div class='testcase'>test_audit2: 二审活动</div></td>
    <td colspan='5' align='center'>

    <!--css div popup start-->
    <a class="popup_link" onfocus='this.blur();' href="javascript:showTestDetail('div_ft1.12')" >
        error</a>

    <div id='div_ft1.12' class="popup_window">
        <div style='text-align: right; color:red;cursor:pointer'>
        <a onfocus='this.blur();' onclick="document.getElementById('div_ft1.12').style.display = 'none' " >
           [x]</a>
        </div>
        <pre>
        
ft1.12: Traceback (most recent call last):
  File "C:\Python34\lib\site-packages\selenium\webdriver\common\service.py", line 76, in start
    stdin=PIPE)
  File "C:\Python34\lib\subprocess.py", line 707, in __init__
    restore_signals, start_new_session)
  File "C:\Python34\lib\subprocess.py", line 990, in _execute_child
    startupinfo)
FileNotFoundError: [WinError 2] 系统找不到指定的文件。

During handling of the above exception, another exception occurred:

Traceback (most recent call last):
  File "e:\activity\testcase\test_activity.py", line 23, in setUp
    self.driver=activitypage(webdriver.Chrome(ospath+'/chromedriver.exe'))
  File "C:\Python34\lib\site-packages\selenium\webdriver\chrome\webdriver.py", line 68, in __init__
    self.service.start()
  File "C:\Python34\lib\site-packages\selenium\webdriver\common\service.py", line 83, in start
    os.path.basename(self.path), self.start_error_message)
selenium.common.exceptions.WebDriverException: Message: 'chromedriver.exe' executable needs to be in PATH. Please see https://sites.google.com/a/chromium.org/chromedriver/home

Traceback (most recent call last):
  File "C:\Python34\lib\site-packages\selenium\webdriver\common\service.py", line 76, in start
    stdin=PIPE)
  File "C:\Python34\lib\subprocess.py", line 707, in __init__
    restore_signals, start_new_session)
  File "C:\Python34\lib\subprocess.py", line 990, in _execute_child
    startupinfo)
FileNotFoundError: [WinError 2] 系统找不到指定的文件。

During handling of the above exception, another exception occurred:

Traceback (most recent call last):
  File "e:\activity\testcase\test_activity.py", line 23, in setUp
    self.driver=activitypage(webdriver.Chrome(ospath+'/chromedriver.exe'))
  File "C:\Python34\lib\site-packages\selenium\webdriver\chrome\webdriver.py", line 68, in __init__
    self.service.start()
  File "C:\Python34\lib\site-packages\selenium\webdriver\common\service.py", line 83, in start
    os.path.basename(self.path), self.start_error_message)
selenium.common.exceptions.WebDriverException: Message: 'chromedriver.exe' executable needs to be in PATH. Please see https://sites.google.com/a/chromium.org/chromedriver/home



        </pre>
    </div>
    <!--css div popup end-->

    </td>
</tr>

<tr class='errorClass'>
    <td>test_app_activity.test_app_activity</td>
    <td>1</td>
    <td>0</td>
    <td>0</td>
    <td>1</td>
    <td><a href="javascript:showClassDetail('c2',1)">Detail</a></td>
</tr>

<tr id='ft2.1' class='none'>
    <td class='errorCase'><div class='testcase'>test_apply</div></td>
    <td colspan='5' align='center'>

    <!--css div popup start-->
    <a class="popup_link" onfocus='this.blur();' href="javascript:showTestDetail('div_ft2.1')" >
        error</a>

    <div id='div_ft2.1' class="popup_window">
        <div style='text-align: right; color:red;cursor:pointer'>
        <a onfocus='this.blur();' onclick="document.getElementById('div_ft2.1').style.display = 'none' " >
           [x]</a>
        </div>
        <pre>
        
ft2.1: Traceback (most recent call last):
  File "C:\Python34\lib\site-packages\selenium\webdriver\common\service.py", line 76, in start
    stdin=PIPE)
  File "C:\Python34\lib\subprocess.py", line 707, in __init__
    restore_signals, start_new_session)
  File "C:\Python34\lib\subprocess.py", line 990, in _execute_child
    startupinfo)
FileNotFoundError: [WinError 2] 系统找不到指定的文件。

During handling of the above exception, another exception occurred:

Traceback (most recent call last):
  File "e:\activity\testcase\test_app_activity.py", line 10, in setUp
    self.driver=Apply(webdriver.Chrome(ospath+'/chromedriver.exe'))
  File "C:\Python34\lib\site-packages\selenium\webdriver\chrome\webdriver.py", line 68, in __init__
    self.service.start()
  File "C:\Python34\lib\site-packages\selenium\webdriver\common\service.py", line 83, in start
    os.path.basename(self.path), self.start_error_message)
selenium.common.exceptions.WebDriverException: Message: 'chromedriver.exe' executable needs to be in PATH. Please see https://sites.google.com/a/chromium.org/chromedriver/home

Traceback (most recent call last):
  File "C:\Python34\lib\site-packages\selenium\webdriver\common\service.py", line 76, in start
    stdin=PIPE)
  File "C:\Python34\lib\subprocess.py", line 707, in __init__
    restore_signals, start_new_session)
  File "C:\Python34\lib\subprocess.py", line 990, in _execute_child
    startupinfo)
FileNotFoundError: [WinError 2] 系统找不到指定的文件。

During handling of the above exception, another exception occurred:

Traceback (most recent call last):
  File "e:\activity\testcase\test_app_activity.py", line 10, in setUp
    self.driver=Apply(webdriver.Chrome(ospath+'/chromedriver.exe'))
  File "C:\Python34\lib\site-packages\selenium\webdriver\chrome\webdriver.py", line 68, in __init__
    self.service.start()
  File "C:\Python34\lib\site-packages\selenium\webdriver\common\service.py", line 83, in start
    os.path.basename(self.path), self.start_error_message)
selenium.common.exceptions.WebDriverException: Message: 'chromedriver.exe' executable needs to be in PATH. Please see https://sites.google.com/a/chromium.org/chromedriver/home



        </pre>
    </div>
    <!--css div popup end-->

    </td>
</tr>

<tr id='total_row'>
    <td>Total</td>
    <td>13</td>
    <td>0</td>
    <td>0</td>
    <td>13</td>
    <td>&nbsp;</td>
</tr>
</table>

<div id='ending'>&nbsp;</div>

</body>
</html>
